Workbook

Sheet Cover
B2: CloudMigrate.in
B3: Cloud Security Assessment Checklist — Azure
B4: Microsoft Azure · v1.0 · generated 21 Oct 2026
B6: Purpose | C6: Assess Azure posture against Microsoft Cloud Security Benchmark / CIS Microsoft Azure Foundations and Indian regulatory obligations.
B7: Customer
B8: Project / programme
B9: Prepared by
B10: Reviewed by
B11: Last updated
B13: How to use | C13: 1. Work area by area; record Result (Pass / Partial / Fail) and evidence for each control.
C14: 2. Severity reflects impact if the control fails; prioritise Critical and High fails.
C15: 3. The Regulation column shows the Indian obligation most affected — validate with your compliance team.
C16: 4. The Summary sheet tracks progress; export failing rows to your remediation tracker.
B18: Reference | C18: Target regions: Central India (Pune), South India (Chennai), West India (Mumbai)
C19: Landing zone: Azure Landing Zones (CAF) — management groups, Azure Policy
C20: Security baseline: Microsoft Cloud Security Benchmark / CIS Microsoft Azure Foundations
B23: Template provided as-is for planning purposes. Validate vendor programme terms and service availability before relying on them.

Sheet Summary
A1: Area | B1: Items | C1: Done | D1: In progress | E1: Blocked | F1: Not started | G1: N/A | H1: % complete
A2: Identity & access | B2: =COUNTIF('Controls'!$B:$B,A2) | C2: =COUNTIFS('Controls'!$B:$B,$A2,'Controls'!$H:$H,"Done") | D2: =COUNTIFS('Controls'!$B:$B,$A2,'Controls'!$H:$H,"In progress") | E2: =COUNTIFS('Controls'!$B:$B,$A2,'Controls'!$H:$H,"Blocked") | F2: =COUNTIFS('Controls'!$B:$B,$A2,'Controls'!$H:$H,"Not started") | G2: =COUNTIFS('Controls'!$B:$B,$A2,'Controls'!$H:$H,"N/A") | H2: =IFERROR(C2/(B2-G2),0)
A3: Logging & monitoring | B3: =COUNTIF('Controls'!$B:$B,A3) | C3: =COUNTIFS('Controls'!$B:$B,$A3,'Controls'!$H:$H,"Done") | D3: =COUNTIFS('Controls'!$B:$B,$A3,'Controls'!$H:$H,"In progress") | E3: =COUNTIFS('Controls'!$B:$B,$A3,'Controls'!$H:$H,"Blocked") | F3: =COUNTIFS('Controls'!$B:$B,$A3,'Controls'!$H:$H,"Not started") | G3: =COUNTIFS('Controls'!$B:$B,$A3,'Controls'!$H:$H,"N/A") | H3: =IFERROR(C3/(B3-G3),0)
A4: Data protection | B4: =COUNTIF('Controls'!$B:$B,A4) | C4: =COUNTIFS('Controls'!$B:$B,$A4,'Controls'!$H:$H,"Done") | D4: =COUNTIFS('Controls'!$B:$B,$A4,'Controls'!$H:$H,"In progress") | E4: =COUNTIFS('Controls'!$B:$B,$A4,'Controls'!$H:$H,"Blocked") | F4: =COUNTIFS('Controls'!$B:$B,$A4,'Controls'!$H:$H,"Not started") | G4: =COUNTIFS('Controls'!$B:$B,$A4,'Controls'!$H:$H,"N/A") | H4: =IFERROR(C4/(B4-G4),0)
A5: Network security | B5: =COUNTIF('Controls'!$B:$B,A5) | C5: =COUNTIFS('Controls'!$B:$B,$A5,'Controls'!$H:$H,"Done") | D5: =COUNTIFS('Controls'!$B:$B,$A5,'Controls'!$H:$H,"In progress") | E5: =COUNTIFS('Controls'!$B:$B,$A5,'Controls'!$H:$H,"Blocked") | F5: =COUNTIFS('Controls'!$B:$B,$A5,'Controls'!$H:$H,"Not started") | G5: =COUNTIFS('Controls'!$B:$B,$A5,'Controls'!$H:$H,"N/A") | H5: =IFERROR(C5/(B5-G5),0)
A6: Workload security | B6: =COUNTIF('Controls'!$B:$B,A6) | C6: =COUNTIFS('Controls'!$B:$B,$A6,'Controls'!$H:$H,"Done") | D6: =COUNTIFS('Controls'!$B:$B,$A6,'Controls'!$H:$H,"In progress") | E6: =COUNTIFS('Controls'!$B:$B,$A6,'Controls'!$H:$H,"Blocked") | F6: =COUNTIFS('Controls'!$B:$B,$A6,'Controls'!$H:$H,"Not started") | G6: =COUNTIFS('Controls'!$B:$B,$A6,'Controls'!$H:$H,"N/A") | H6: =IFERROR(C6/(B6-G6),0)
A7: Resilience | B7: =COUNTIF('Controls'!$B:$B,A7) | C7: =COUNTIFS('Controls'!$B:$B,$A7,'Controls'!$H:$H,"Done") | D7: =COUNTIFS('Controls'!$B:$B,$A7,'Controls'!$H:$H,"In progress") | E7: =COUNTIFS('Controls'!$B:$B,$A7,'Controls'!$H:$H,"Blocked") | F7: =COUNTIFS('Controls'!$B:$B,$A7,'Controls'!$H:$H,"Not started") | G7: =COUNTIFS('Controls'!$B:$B,$A7,'Controls'!$H:$H,"N/A") | H7: =IFERROR(C7/(B7-G7),0)
A8: Governance | B8: =COUNTIF('Controls'!$B:$B,A8) | C8: =COUNTIFS('Controls'!$B:$B,$A8,'Controls'!$H:$H,"Done") | D8: =COUNTIFS('Controls'!$B:$B,$A8,'Controls'!$H:$H,"In progress") | E8: =COUNTIFS('Controls'!$B:$B,$A8,'Controls'!$H:$H,"Blocked") | F8: =COUNTIFS('Controls'!$B:$B,$A8,'Controls'!$H:$H,"Not started") | G8: =COUNTIFS('Controls'!$B:$B,$A8,'Controls'!$H:$H,"N/A") | H8: =IFERROR(C8/(B8-G8),0)
A9: Incident response | B9: =COUNTIF('Controls'!$B:$B,A9) | C9: =COUNTIFS('Controls'!$B:$B,$A9,'Controls'!$H:$H,"Done") | D9: =COUNTIFS('Controls'!$B:$B,$A9,'Controls'!$H:$H,"In progress") | E9: =COUNTIFS('Controls'!$B:$B,$A9,'Controls'!$H:$H,"Blocked") | F9: =COUNTIFS('Controls'!$B:$B,$A9,'Controls'!$H:$H,"Not started") | G9: =COUNTIFS('Controls'!$B:$B,$A9,'Controls'!$H:$H,"N/A") | H9: =IFERROR(C9/(B9-G9),0)
A10: Total | B10: =SUM(B2:B9) | C10: =SUM(C2:C9) | D10: =SUM(D2:D9) | E10: =SUM(E2:E9) | F10: =SUM(F2:F9) | G10: =SUM(G2:G9) | H10: =IFERROR(C10/(B10-G10),0)
A12: Go-live readiness rule: all Critical items Done or N/A, no Blocked items, ≥ 90% overall.
A13: Critical items not yet Done | B13: =COUNTIFS('Controls'!$G:$G,"Critical",'Controls'!$H:$H,"<>Done",'Controls'!$H:$H,"<>N/A",'Controls'!$A:$A,"<>ID")

Sheet Controls
A1: ID | B1: Area | C1: Control | D1: Azure service / method | E1: Benchmark ref | F1: Regulation | G1: Priority | H1: Status | I1: Result | J1: Evidence | K1: Owner | L1: Remediation / due
A2: SEC-001 | B2: Identity & access | C2: MFA enforced for all human administrators | D2: Microsoft Entra ID with Privileged Identity Management and Conditional Access | E2: MCSB / CIS Azure IAM | F2: DPDP s.8(5) safeguards | G2: Critical | H2: Not started
A3: SEC-002 | B3: Identity & access | C3: No standing privileged access; just-in-time elevation | D3: Azure Lighthouse delegated access + PIM | E3: MCSB / CIS Azure IAM | F3: RBI cyber-resilience | G3: Critical | H3: Not started
A4: SEC-003 | B4: Identity & access | C4: Root / global admin / super-admin accounts locked down and alerted | D4: Hardware MFA, no access keys, alert on use. | E4: MCSB / CIS Azure IAM | G4: Critical | H4: Not started
A5: SEC-004 | B5: Identity & access | C5: Break-glass accounts documented and tested quarterly | E5: MCSB / CIS Azure IAM | G5: High | H5: Not started
A6: SEC-005 | B6: Identity & access | C6: Service identities use workload identity, not long-lived keys | D6: Rotate or remove keys older than 90 days. | E6: MCSB / CIS Azure IAM | G6: High | H6: Not started
A7: SEC-006 | B7: Identity & access | C7: Access reviews performed quarterly for privileged roles | E7: ISO 27001 A.5.18 | F7: SEBI cloud framework | G7: High | H7: Not started
A8: SEC-007 | B8: Identity & access | C8: Guest / external identities reviewed and expired | E8: MCSB / CIS Azure IAM | G8: Medium | H8: Not started
A9: SEC-008 | B9: Logging & monitoring | C9: Control-plane audit logs enabled organisation-wide | D9: Diagnostic settings to a central Log Analytics workspace; Activity Log export | E9: MCSB / CIS Azure Logging | F9: CERT-In 2022 | G9: Critical | H9: Not started
A10: SEC-009 | B10: Logging & monitoring | C10: Logs retained ≥ 180 days in India and protected from deletion | D10: Diagnostic settings to a central Log Analytics workspace; Activity Log export | E10: MCSB / CIS Azure Logging | F10: CERT-In 2022 | G10: Critical | H10: Not started
A11: SEC-010 | B11: Logging & monitoring | C11: Time synchronisation to approved NTP sources | D11: CERT-In expects NIC / NPL NTP sync for ICT systems. | E11: CIS v8 8.4 | F11: CERT-In 2022 | G11: High | H11: Not started
A12: SEC-011 | B12: Logging & monitoring | C12: Threat detection enabled in all regions and accounts | D12: Defender for Servers / SQL / Storage / Containers | E12: MCSB / CIS Azure Monitoring | G12: Critical | H12: Not started
A13: SEC-012 | B13: Logging & monitoring | C13: Security posture management enabled with a tracked score | D13: Microsoft Defender for Cloud (Defender CSPM, Secure Score) | E13: MCSB / CIS Azure | G13: High | H13: Not started
A14: SEC-013 | B14: Logging & monitoring | C14: SIEM ingests identity, control-plane, network and endpoint logs | D14: Microsoft Sentinel | E14: CIS v8 8.9 | G14: High | H14: Not started
A15: SEC-014 | B15: Logging & monitoring | C15: Alerts for root / admin use, policy changes, key deletion | E15: MCSB / CIS Azure Monitoring | G15: High | H15: Not started
A16: SEC-015 | B16: Data protection | C16: Encryption at rest everywhere; customer-managed keys for regulated data | D16: Azure Key Vault / Managed HSM with customer-managed keys | E16: MCSB / CIS Azure Storage | F16: RBI / IRDAI | G16: Critical | H16: Not started
A17: SEC-016 | B17: Data protection | C17: Encryption in transit (TLS 1.2+) enforced | E17: CIS v8 3.10 | G17: High | H17: Not started
A18: SEC-017 | B18: Data protection | C18: No public object storage unless explicitly approved | E18: MCSB / CIS Azure Storage | F18: DPDP | G18: Critical | H18: Not started
A19: SEC-018 | B19: Data protection | C19: Personal-data discovery and classification running | D19: Microsoft Purview sensitivity labels and DLP | E19: CIS v8 3.2 | F19: DPDP | G19: High | H19: Not started
A20: SEC-019 | B20: Data protection | C20: Key rotation and separation of key administrators | D20: Azure Key Vault / Managed HSM with customer-managed keys | E20: MCSB / CIS Azure KMS | G20: Medium | H20: Not started
A21: SEC-020 | B21: Data protection | C21: Non-production data masked or synthetic | E21: ISO 27001 A.8.11 | F21: DPDP | G21: High | H21: Not started
A22: SEC-021 | B22: Network security | C22: No management ports (22 / 3389) open to the internet | D22: Use bastion / session manager. | E22: MCSB / CIS Azure Networking | G22: Critical | H22: Not started
A23: SEC-022 | B23: Network security | C23: Default-deny network policies and segmentation between tiers | D23: Hub-and-spoke or Virtual WAN with Azure Firewall | E23: MCSB / CIS Azure Networking | G23: High | H23: Not started
A24: SEC-023 | B24: Network security | C24: WAF and DDoS protection on internet-facing applications | D24: Azure Front Door / Application Gateway WAF, DDoS Protection | E24: CIS v8 13.10 | G24: High | H24: Not started
A25: SEC-024 | B25: Network security | C25: Private endpoints for PaaS data services | E25: MCSB / CIS Azure Networking | G25: High | H25: Not started
A26: SEC-025 | B26: Network security | C26: Egress filtered through central inspection | D26: Hub-and-spoke or Virtual WAN with Azure Firewall | E26: CIS v8 13 | G26: Medium | H26: Not started
A27: SEC-026 | B27: Network security | C27: Flow logs enabled on critical networks | E27: MCSB / CIS Azure Logging | F27: CERT-In 2022 | G27: Medium | H27: Not started
A28: SEC-027 | B28: Workload security | C28: Vulnerability scanning of hosts, containers and images | D28: Defender for Servers / SQL / Storage / Containers | E28: CIS v8 7 | G28: High | H28: Not started
A29: SEC-028 | B29: Workload security | C29: Critical patches applied within 14 days | D29: Azure Update Manager (Azure + Arc-enabled servers) | E29: CIS v8 7.3 | F29: RBI | G29: High | H29: Not started
A30: SEC-029 | B30: Workload security | C30: Endpoint detection and response on all servers | D30: Defender for Servers / SQL / Storage / Containers | E30: CIS v8 10 | G30: High | H30: Not started
A31: SEC-030 | B31: Workload security | C31: Hardened images (CIS level 1) used as baselines | E31: CIS v8 4.1 | G31: Medium | H31: Not started
A32: SEC-031 | B32: Workload security | C32: Secrets stored in a vault, not code or config | D32: Azure Key Vault / Managed HSM with customer-managed keys | E32: CIS v8 3.11 | G32: High | H32: Not started
A33: SEC-032 | B33: Resilience | C33: Immutable / locked backups for tier-1 data | D33: Azure Backup with immutable vaults and soft delete | E33: CIS v8 11 | F33: RBI | G33: Critical | H33: Not started
A34: SEC-033 | B34: Resilience | C34: Restore tests performed and documented | E34: CIS v8 11.5 | F34: SEBI | G34: High | H34: Not started
A35: SEC-034 | B35: Resilience | C35: DR plan tested within the last 12 months | D35: Azure Site Recovery / zone-redundant services | E35: ISO 27001 A.5.30 | F35: RBI / SEBI | G35: High | H35: Not started
A36: SEC-035 | B36: Governance | C36: Guardrails / policies prevent non-compliant deployments | D36: Azure Landing Zones (CAF) — management groups, Azure Policy | E36: MCSB / CIS Azure | G36: High | H36: Not started
A37: SEC-036 | B37: Governance | C37: Resources restricted to approved Indian regions where residency applies | D37: Central India (Pune), South India (Chennai), West India (Mumbai) | E37: MCSB / CIS Azure | F37: DPDP / sector rules | G37: High | H37: Not started
A38: SEC-037 | B38: Governance | C38: Asset inventory complete and owners assigned | E38: CIS v8 1 | G38: Medium | H38: Not started
A39: SEC-038 | B39: Governance | C39: Third-party and support access logged and time-bound | E39: ISO 27001 A.5.19 | F39: RBI outsourcing | G39: High | H39: Not started
A40: SEC-039 | B40: Incident response | C40: Cloud IR playbooks for credential compromise, data exposure, ransomware | E40: CIS v8 17 | F40: CERT-In 2022 | G40: High | H40: Not started
...
